<?xml version='1.0'?>

<robot name="udacity_bot" xmlns:xacro="http://www.ros.org/wiki/xacro">
 <xacro:include filename="$(find slam_project)/urdf/slam_bot.gazebo" />
  <link name="robot_footprint"></link>
 
  <joint name="robot_footprint_joint" type="fixed">
    <origin xyz="0 0 0" rpy="0 0 0" />
    <parent link="robot_footprint"/>
    <child link="chassis" />
  </joint>

  <link name='chassis'>
    <pose>0 0 0 0 0 0</pose>

    <inertial>
      <mass value="1.0"/>
      <origin xyz="0 0 0" rpy=" 0 0 0"/>
      <inertia
          ixx="0.1" ixy="0" ixz="0"
          iyy="0.1" iyz="0"
          izz="0.1"
      />
    </inertial>
	<collision name='chassis_collision'>
      <origin xyz="0 0 0" rpy=" 0 0 0"/> 
      <geometry>
        <cylinder radius=".2" length=".02"/>
      </geometry>
    </collision>

    <visual name='chassis_visual'>
      <origin xyz="0 0 0" rpy=" 0 0 0"/>
      <geometry>
        <cylinder radius=".2" length=".02"/>
      </geometry>
      <material name="chassis base">
        <color rgba="1 1 0 1"/>
      </material>
    </visual>
   
    <collision name='left_leg_collision'>
      <origin xyz="0 -0.15 0.2" rpy=" 0 0 0"/> 
      <geometry>
        <cylinder radius=".01" length=".4"/>
      </geometry>
    </collision>

    <visual name='left_leg_visual'>
      <origin xyz="0 -0.15 0.2" rpy=" 0 0 0"/>
      <geometry>
        <cylinder radius=".01" length=".4"/>
      </geometry>
    </visual>
     <collision name='right_leg_collision'>
      <origin xyz="0 0.15 0.2" rpy=" 0 0 0"/> 
      <geometry>
        <cylinder radius=".01" length=".4"/>
      </geometry>
    </collision>

    <visual name='right_leg_visual'>
      <origin xyz="0 0.15 0.2" rpy=" 0 0 0"/>
      <geometry>
        <cylinder radius=".01" length=".4"/>
      </geometry>
    </visual>
   
    <collision name='front_leg_collision'>
      <origin xyz="0.15 0 0.2" rpy=" 0 0 0"/> 
      <geometry>
        <cylinder radius=".01" length=".4"/>
      </geometry>
    </collision>

    <visual name='front_leg_visual'>
      <origin xyz="0.15 0 0.2" rpy=" 0 0 0"/>
      <geometry>
        <cylinder radius=".01" length=".4"/>
      </geometry>
    </visual>
     <collision name='back_leg_collision'>
      <origin xyz="-0.15 0 0.2" rpy=" 0 0 0"/> 
      <geometry>
        <cylinder radius=".01" length=".4"/>
      </geometry>
    </collision>

    <visual name='back_leg_visual'>
      <origin xyz="-0.15 0 0.2" rpy=" 0 0 0"/>
      <geometry>
        <cylinder radius=".01" length=".4"/>
      </geometry>
    </visual>
    
     <collision name='disk2_collision'>
      <origin xyz="0 0 0.4" rpy=" 0 0 0"/> 
      <geometry>
        <cylinder radius=".3" length=".02"/>
      </geometry>
    </collision>

    <visual name='disk2_visual'>
      <origin xyz="0 0 0.4" rpy=" 0 0 0"/>
      <geometry>
        <cylinder radius=".3" length=".02"/>
      </geometry>
    </visual>
    
    <collision name='left_leg2_collision'>
      <origin xyz="0 -0.15 0.6" rpy=" 0 0 0"/> 
      <geometry>
        <cylinder radius=".01" length=".4"/>
      </geometry>
    </collision>

    <visual name='left_leg2_visual'>
      <origin xyz="0 -0.15 0.6" rpy=" 0 0 0"/>
      <geometry>
        <cylinder radius=".01" length=".4"/>
      </geometry>
    </visual>
     <collision name='right_leg2_collision'>
      <origin xyz="0 0.15 0.6" rpy=" 0 0 0"/> 
      <geometry>
        <cylinder radius=".01" length=".4"/>
      </geometry>
    </collision>

    <visual name='right_leg2_visual'>
      <origin xyz="0 0.15 0.6" rpy=" 0 0 0"/>
      <geometry>
        <cylinder radius=".01" length=".4"/>
      </geometry>
    </visual>
   <collision name='disk3_collision'>
      <origin xyz="0 0 0.8" rpy=" 0 0 0"/> 
      <geometry>
        <cylinder radius=".3" length=".02"/>
      </geometry>
    </collision>

    <visual name='disk3_visual'>
      <origin xyz="0 0 0.8" rpy=" 0 0 0"/>
      <geometry>
        <cylinder radius=".3" length=".02"/>
      </geometry>
    </visual>
     <collision name='back_caster_collision'>
      <origin xyz="-0.15 0 -0.05" rpy=" 0 0 0"/>
      <geometry>
        <sphere radius="0.05"/>
      </geometry>
    </collision>
    <visual name='back_caster_visual'>
      <origin xyz="-0.15 0 -0.05" rpy=" 0 0 0"/>
      <geometry>
        <sphere radius="0.05"/>
      </geometry>
    </visual>

    <collision name='front_caster_collision'>
      <origin xyz="0.15 0 -0.05" rpy=" 0 0 0"/>
      <geometry>
        <sphere radius="0.0499"/>
      </geometry>
    </collision>

    <visual name='front_caster_visual'>
      <origin xyz="0.15 0 -0.05" rpy=" 0 0 0"/>
      <geometry>
        <sphere radius="0.05"/>
      </geometry>
    </visual>
    </link>
<link name='left_wheel'>
    <pose>0 0 0 0 1.5707 1.5707</pose>
    <inertial>
      <mass value="5.0"/>
      <origin xyz="0.0 0 0" rpy=" 0 1.5707 1.5707"/>
      <inertia
          ixx="0.1" ixy="0" ixz="0"
          iyy="0.1" iyz="0"
          izz="0.1"
      />
    </inertial>

    <collision name='collision'>
      <origin xyz="0 0 0" rpy=" 0 1.5707 1.5707"/> 
      <geometry>
        <cylinder length="0.05" radius="0.1"/>
      </geometry>
    </collision>

    <visual name='left_wheel_visual'>
      <origin xyz="0 0 0" rpy=" 0 1.5707 1.5707"/>
      <geometry>
        <cylinder length="0.05" radius="0.1"/>
      </geometry>
      <material name="">
        <color rgba="0 0 0 1"/>
      </material>
    </visual>
 </link>

<link name='right_wheel'>
    <pose>0 0 0 0 1.5707 1.5707</pose>

    <inertial>
      <mass value="5.0"/>
      <origin xyz="0.0 0 0" rpy=" 0 1.5707 1.5707"/>
      <inertia
          ixx="0.1" ixy="0" ixz="0"
          iyy="0.1" iyz="0"
          izz="0.1"
      />
    </inertial>

    <collision name='collision'>
      <origin xyz="0 0 0" rpy=" 0 1.5707 1.5707"/> 
      <geometry>
        <cylinder length="0.05" radius="0.1"/>
      </geometry>
    </collision>

    <visual name='right_wheel_visual'>
      <origin xyz="0 0 0" rpy=" 0 1.5707 1.5707"/>
      <geometry>
        <cylinder length="0.05" radius="0.1"/>
      </geometry>
       <material name="">
        <color rgba="0 0 0 1"/>
      </material>
    </visual>      
  </link>   
 <link name='camera'>
    <pose>0 0 0 0 0 0</pose>
    <inertial>
      <mass value="0.1"/>
      <origin xyz="0 0 0" rpy=" 0 0 0"/>
      <inertia
          ixx="1e-6" ixy="0" ixz="0"
          iyy="1e-6" iyz="0"
          izz="1e-6"
      />
    </inertial>
    <collision name='collision'>
      <origin xyz="0 0 0" rpy=" 0 0 0"/> 
      <geometry>
        <box size=".05 .05 .05"/>
      </geometry>
    </collision>
    <visual name='camera_visual'>
      <origin xyz="0 0 0" rpy=" 0 0 0"/>
      <geometry>
        <box size=".05 .05 .05"/>
      </geometry>
      <material name="">
        <color rgba="0 1 0 1"/>
      </material>
    </visual>
 </link>
 <link name='hokuyo'>
    <pose>0 0 0 0 0 0</pose>
    <inertial>
      <mass value="0.1"/>
      <origin xyz="0 0 0" rpy=" 0 0 0"/>
      <inertia
          ixx="1e-6" ixy="0" ixz="0"
          iyy="1e-6" iyz="0"
          izz="1e-6"
      />
    </inertial>
    <collision name='collision'>
      <origin xyz="0 0 0" rpy=" 0 0 0"/> 
      <geometry>
        <box size=".1 .1 .1"/>
      </geometry>
    </collision>
    <visual name='hokuyo_visual'>
      <origin xyz="0 0 0" rpy=" 0 0 0"/>
      <geometry>
        <mesh filename="package://slam_project/meshes/hokuyo.dae"/>
      </geometry>
    </visual>
 </link>
 <joint type="continuous" name="left_wheel_hinge">
    <origin xyz="0 0.2 0" rpy="0 0 0"/>
    <child link="left_wheel"/>
    <parent link="chassis"/>
    <axis xyz="0 1 0" rpy="0 0 0"/>
    <limit effort="10000" velocity="1000"/>
    <dynamics damping="1.0" friction="1.0"/>
  </joint>

  <joint type="continuous" name="right_wheel_hinge">
    <origin xyz="0 -0.2 0" rpy="0 0 0"/>
    <child link="right_wheel"/>
    <parent link="chassis"/>
    <axis xyz="0 1 0" rpy="0 0 0"/>
    <limit effort="10000" velocity="1000"/>
    <dynamics damping="1.0" friction="1.0"/>
  </joint>
  <joint type="fixed" name="camera_joint">
    <origin xyz="0.27 0 0.44" rpy="0 0 0"/>
    <child link="camera"/>
    <parent link="chassis"/>
    <axis xyz="0 1 0" rpy="0 0 0"/>
    <limit effort="10000" velocity="1000"/>
    <dynamics damping="1.0" friction="1.0"/>
  </joint> 
  <link name="camera_rgbd_frame"></link>
  <joint name="camera_rgbd_joint" type="fixed">
    <origin xyz="0.06 0 0" rpy="-${pi/2} 0 -${pi/2}"/>
    <parent link="camera"/>
    <child link="camera_rgbd_frame"/>
  </joint>
  <joint type="fixed" name="hokuyo_joint">
    <origin xyz="0 0 0.85" rpy="0 0 0"/>
    <child link="hokuyo"/>
    <parent link="chassis"/>
    <axis xyz="0 0 1" rpy="0 0 0"/>
    <limit effort="10000" velocity="1000"/>
    <dynamics damping="1.0" friction="1.0"/>
  </joint> 
</robot>